Workbook

Sheet Instructions
B2: Excel Practice Workbook: Text Functions, Aggregate Functions & Conditional Formatting
B5: 📘 Welcome
B6: This workbook is designed to help you practice three essential Excel skill areas: Text Functions, Aggregate Functions, and Conditional Formatting. Work through each sheet in order, complete the highlighted task cells, and compare your answers with the reference solutions provided.
B8: 🎯 Learning Objectives
B9: • Manipulate and extract text using LEFT, RIGHT, MID, LEN, FIND/SEARCH, TRIM, SUBSTITUTE, REPLACE.
B10: • Combine text using CONCAT and TEXTJOIN, and change case using UPPER, LOWER, PROPER.
B11: • Summarize numeric data using SUM, AVERAGE, COUNT, COUNTA, MAX, and MIN.
B12: • Apply Conditional Formatting rules: color scales, data bars, icon sets, and highlight rules (above/below average, duplicates, blanks, specific text, Top 10 / Bottom 10).
B13: • Build a simple Dashboard that pulls key metrics from raw data using live formulas.
B15: 🗂️ Workbook Structure
B16: ▪ Instructions — This sheet — overview, objectives, and how to use the workbook.
B17: ▪ Raw Data — 52 rows of sample student data used throughout all practice sheets. Do not edit this sheet.
... B33: Good luck, and have fun exploring Excel! Start with the 'Raw Data' sheet to familiarize yourself with the dataset, then move on to 'Text Functions Practice'.

Sheet Raw Data
A1: Student ID | B1: Full Name | C1: Email | D1: Course | E1: Score1 | F1: Score2 | G1: Score3 | H1: Enrollment Date | I1: Status | J1: Notes
A2: STU1001 | B2: Suresh Nair | C2: suresh.nair1@gmail.com | D2: Machine Learning Basics | F2: 54 | G2: 58 | H2: 45678 | I2: Active | J2: On track for certification
A3: STU1002 | B3: Gaurav Patel | C3: gaurav.patel2@learnhub.org | D3: Power BI Essentials | E3: 47 | F3: 41 | G3: 55 | H3: 45412 | I3: Active | J3: Great participation in class
A4: STU1003 | B4: Ishita Naidu | C4: ishita.naidu3@outlook.com | D4: Power BI Essentials | E4: 59 | F4: 68 | G4: 87 | H4: 45443 | I4: Completed | J4: Needs support with formulas
A5: STU1004 | B5: Alok Mehta | C5: alok.mehta4@yahoo.com | D5: SQL for Data Analysis | E5: 62 | F5: 49 | G5: 63 | H5: 45691 | I5: Active | J5: Excellent progress
A6: STU1005 | B6: Kabir Reddy | C6: kabir.reddy5@upgrad.edu | D6: SQL for Data Analysis | E6: 83 | F6: 56 | G6: 52 | H6: 45674 | I6: Active | J6: Excellent progress
A7: STU1006 | B7: Kabir Patel | C7: kabir.patel6@learnhub.org | D7: Machine Learning Basics | E7: 98 | F7: 80 | G7: 89 | H7: 45486 | I7: Completed | J7: On track for certification
A8: STU1007 | B8: Vikram Gupta | C8: vikram.gupta7@outlook.com | D8: Machine Learning Basics | E8: 50 | F8: 94 | G8: 64 | H8: 45352 | I8: Active
A9: STU1008 | B9: Suresh Desai | C9: suresh.desai8@outlook.com | D9: SQL for Data Analysis | E9: 67 | F9: 53 | G9: 92 | H9: 45437 | I9: Completed | J9: Struggling with syntax
A10: STU1009 | B10: Komal Kumar | C10: komal.kumar9@learnhub.org | D10: Python for Analytics | E10: 79 | F10: 86 | G10: 65 | H10: 45384 | I10: Active | J10: Strong performer
A11: STU1010 | B11: Suresh Khanna | C11: suresh.khanna10@learnhub.org | D11: Business Analytics | E11: 88 | F11: 60 | G11: 99 | H11: 45698 | I11: Active | J11: Needs support with formulas
A12: STU1011 | B12: Payal Bhat | C12: payal.bhat11@yahoo.com | D12: Machine Learning Basics | E12: 49 | G12: 86 | H12: 45668 | I12: Active | J12: Struggling with syntax
A13: STU1012 | B13: Swati Saxena | C13: swati.saxena12@yahoo.com | D13: Python for Analytics | E13: 61 | F13: 48 | G13: 65 | H13: 45682 | I13: Completed | J13: Strong performer
A14: STU1013 | B14: Bhavna Dubey | C14: bhavna.dubey13@yahoo.com | D14: Power BI Essentials | E14: 68 | F14: 54 | G14: 58 | H14: 45561 | I14: Active | J14: Needs support with formulas
A15: STU1014 | B15: Sneha Das | C15: sneha.das14@outlook.com | D15: Power BI Essentials | E15: 83 | F15: 44 | G15: 74 | H15: 45496 | I15: Completed
A16: STU1015 | B16: Anjali Bose | C16: anjali.bose15@learnhub.org | D16: Data Science Fundamentals | E16: 88 | F16: 86 | G16: 57 | H16: 45650 | I16: Dropped | J16: Strong performer
A17: STU1016 | B17: Kritika Sen | C17: kritika.sen16@upgrad.edu | D17: Advanced Excel | E17: 63 | F17: 67 | G17: 60 | H17: 45533 | I17: Active | J17: On track for certification
A18: STU1017 | B18: Manoj Bose | C18: manoj.bose17@learnhub.org | D18: Python for Analytics | E18: 77 | F18: 98 | G18: 56 | H18: 45621 | I18: Active | J18: Struggling with syntax
A19: STU1018 | B19: Deepak Ghosh | C19: deepak.ghosh18@outlook.com | D19: Python for Analytics | E19: 68 | F19: 88 | G19: 60 | H19: 45577 | I19: On Hold
A20: STU1019 | B20: Aarav Ghosh | C20: aarav.ghosh19@upgrad.edu | D20: Statistics for Data Science | E20: 46 | F20: 47 | G20: 73 | H20: 45458 | I20: Active | J20: Requested extra practice
A21: STU1020 | B21: Vivek Patel | C21: vivek.patel20@gmail.com | D21: Statistics for Data Science | E21: 97 | F21: 44 | G21: 98 | H21: 45573 | I21: Completed | J21: Missed last session
A22: STU1021 | B22: Ashish Chauhan | C22: ashish.chauhan21@learnhub.org | D22: Python for Analytics | E22: 61 | F22: 73 | G22: 88 | H22: 45517 | I22: On Hold
A23: STU1022 | B23: Alok Dutta | C23: alok.dutta22@outlook.com | D23: Machine Learning Basics | E23: 70 | F23: 82 | G23: 91 | H23: 45492 | I23: Active
A24: STU1023 | B24: Yash Nair | C24: yash.nair23@outlook.com | D24: Business Analytics | E24: 49 | F24: 61 | G24: 51 | H24: 45602 | I24: Completed | J24: Great participation in class
A25: STU1024 | B25: Siddharth Sharma | C25: siddharth.sharma24@gmail.com | D25: Data Science Fundamentals | E25: 59 | F25: 44 | G25: 52 | H25: 45470 | I25: Active | J25: Requested extra practice
A26: STU1025 | B26: Pooja Bajaj | C26: pooja.bajaj25@yahoo.com | D26: Business Analytics | E26: 79 | F26: 48 | G26: 96 | H26: 45593 | I26: Completed | J26: Requested extra practice
A27: STU1026 | B27: Naveen Chauhan | C27: naveen.chauhan26@yahoo.com | D27: Business Analytics | E27: 51 | F27: 46 | G27: 92 | H27: 45521 | I27: Active
A28: STU1027 | B28: Nandini Dutta | C28: nandini.dutta27@gmail.com | D28: Advanced Excel | E28: 48 | F28: 65 | G28: 96 | H28: 45474 | I28: Completed | J28: Excellent progress
A29: STU1028 | B29: Neha Chopra | C29: neha.chopra28@outlook.com | D29: Statistics for Data Science | E29: 53 | F29: 67 | G29: 61 | H29: 45443 | I29: Active | J29: Excellent progress
A30: STU1029 | B30: Yash Naidu | C30: yash.naidu29@gmail.com | D30: Data Science Fundamentals | E30: 86 | F30: 74 | G30: 50 | H30: 45348 | I30: Dropped | J30: Requested extra practice
A31: STU1030 | B31: Aditya Mishra | C31: aditya.mishra30@yahoo.com | D31: Statistics for Data Science | E31: 58 | F31: 95 | G31: 75 | H31: 45331 | I31: Active | J31: Needs support with formulas
A32: STU1031 | B32: Kabir Patel | C32: kabir.bose31@yahoo.com | D32: Machine Learning Basics | E32: 72 | F32: 84 | G32: 96 | H32: 45585 | I32: Completed
A33: STU1032 | B33: Meera Chopra | C33: meera.chopra32@upgrad.edu | D33: Business Analytics | E33: 48 | F33: 77 | G33: 97 | H33: 45578 | I33: Active | J33: Submitted assignment late
A34: STU1033 | B34: Priya Singh | C34: priya.singh33@learnhub.org | D34: Statistics for Data Science | E34: 77 | F34: 98 | G34: 83 | H34: 45381 | I34: Active
A35: STU1034 | B35: Ananya Joshi | C35: ananya.joshi34@gmail.com | D35: Advanced Excel | E35: 88 | F35: 95 | G35: 65 | H35: 45507 | I35: Active | J35: Great participation in class
A36: STU1035 | B36: Neha Dubey | C36: neha.dubey35@learnhub.org | D36: Data Science Fundamentals | E36: 84 | F36: 45 | G36: 76 | H36: 45637 | I36: Completed
A37: STU1036 | B37: Sanjay Bose | C37: sanjay.bose36@outlook.com | D37: SQL for Data Analysis | E37: 60 | F37: 56 | G37: 75 | H37: 45368 | I37: Completed | J37: Strong performer
A38: STU1037 | B38: Nandini Bhat | C38: nandini.bhat37@gmail.com | D38: Data Science Fundamentals | E38: 74 | F38: 79 | G38: 86 | H38: 45352 | I38: Active | J38: Requested extra practice
A39: STU1038 | B39: Deepak Bose | C39: deepak.bose38@outlook.com | D39: SQL for Data Analysis | E39: 49 | F39: 96 | G39: 65 | H39: 45490 | I39: Active
A40: STU1039 | B40: Gaurav Arora | C40: gaurav.arora39@upgrad.edu | D40: Data Science Fundamentals | E40: 87 | F40: 92 | G40: 85 | H40: 45454 | I40: Dropped | J40: Excellent progress
...

Sheet Text Functions Practice
A1: TEXT FUNCTIONS PRACTICE
A3: HOW TO USE THIS SHEET: Work through Tasks 1-12 below. Each task shows sample data pulled live from the Raw Data sheet. Type your own formula into the yellow YOUR FORMULA cell. A worked SUGGESTED SOLUTION is shown alongside in gray italics for reference - try it yourself first! Functions covered: LEFT, RIGHT, MID, FIND/SEARCH, LEN, UPPER, LOWER, PROPER, TRIM, SUBSTITUTE, REPLACE, and CONCAT/TEXTJOIN.
A8: Legend: | B8: Yellow = Your Task | C8: Gray italics = Suggested Solution
A10: TASK 1 BEGINNER Extract First Name (LEFT)
A11: Instructions: Use LEFT together with FIND to pull the first name out of the Full Name in column B.
A12: # | B12: Full Name | C12: YOUR FORMULA (TASK)
A13: 1 | B13: ='Raw Data'!B2 -> Suresh Nair | C13: =LEFT(B13,FIND(" ",B13)) -> Suresh
A14: 2 | B14: ='Raw Data'!B3 -> Gaurav Patel | C14: =LEFT(B14,FIND(" ",B14)) -> Gaurav
A15: 3 | B15: ='Raw Data'!B4 -> Ishita Naidu | C15: =LEFT(B15,FIND(" ",B15)) -> Ishita
A16: 4 | B16: ='Raw Data'!B5 -> Alok Mehta | C16: =LEFT(B16,FIND(" ",B16)) -> Alok
A17: 5 | B17: ='Raw Data'!B6 -> Kabir Reddy | C17: =LEFT(B17,FIND(" ",B17)) -> Kabir
A19: TASK 2 INTERMEDIATE Extract Last Name (RIGHT)
A20: Instructions: Use RIGHT together with LEN and FIND to pull the last name out of the Full Name.
A21: # | B21: Full Name | C21: YOUR FORMULA (TASK)
A22: 1 | B22: ='Raw Data'!B2 -> Suresh Nair | C22: =RIGHT(B22,LEN(B22)-FIND(" ",B22)+1) -> Nair
A23: 2 | B23: ='Raw Data'!B3 -> Gaurav Patel | C23: =RIGHT(B23,LEN(B23)-FIND(" ",B23)+1) -> Patel
A24: 3 | B24: ='Raw Data'!B4 -> Ishita Naidu | C24: =RIGHT(B24,LEN(B24)-FIND(" ",B24)+1) -> Naidu
A25: 4 | B25: ='Raw Data'!B5 -> Alok Mehta | C25: =RIGHT(B25,LEN(B25)-FIND(" ",B25)+1) -> Mehta
A26: 5 | B26: ='Raw Data'!B6 -> Kabir Reddy | C26: =RIGHT(B26,LEN(B26)-FIND(" ",B26)+1) -> Reddy
A28: TASK 3 BEGINNER Extract ID Number (MID)
A29: Instructions: Use MID to extract the 4-digit number from the Student ID (starts at character 4, is 4 characters long).
A30: # | B30: Student ID | C30: YOUR FORMULA (TASK) | D30: SUGGESTED SOLUTION
A31: 1 | B31: ='Raw Data'!A2 -> STU1001 | C31: =MID(B31,4,4) -> 1001 | D31: 1001
A32: 2 | B32: ='Raw Data'!A3 -> STU1002 | C32: =MID(B32,4,4) -> 1002
A33: 3 | B33: ='Raw Data'!A4 -> STU1003 | C33: =MID(B33,4,4) -> 1003
A34: 4 | B34: ='Raw Data'!A5 -> STU1004 | C34: =MID(B34,4,4) -> 1004
A35: 5 | B35: ='Raw Data'!A6 -> STU1005 | C35: =MID(B35,4,4) -> 1005
A37: TASK 4 BEGINNER Locate the @ Symbol (FIND/SEARCH)
A38: Instructions: Use FIND (case-sensitive) or SEARCH (case-insensitive) to return the character position of "@" within the Email.
A39: # | B39: Email | C39: YOUR FORMULA (TASK) | D39: SUGGESTED SOLUTION
A40: 1 | B40: ='Raw Data'!C2 -> suresh.nair1@gmail.com | C40: =FIND("@",B40) -> 13 | D40: 13
A41: 2 | B41: ='Raw Data'!C3 -> gaurav.patel2@learnhub.org | C41: =FIND("@",B41) -> 14
A42: 3 | B42: ='Raw Data'!C4 -> ishita.naidu3@outlook.com | C42: =FIND("@",B42) -> 14
A43: 4 | B43: ='Raw Data'!C5 -> alok.mehta4@yahoo.com | C43: =FIND("@",B43) -> 12
A44: 5 | B44: ='Raw Data'!C6 -> kabir.reddy5@upgrad.edu | C44: =FIND("@",B44) -> 13
A46: TASK 5 INTERMEDIATE Extract the Domain (MID + FIND)
A47: Instructions: Combine MID and FIND to extract everything after the "@" symbol in the Email address.
A48: # | B48: Email | C48: YOUR FORMULA (TASK) | D48: SUGGESTED SOLUTION
A49: 1 | B49: ='Raw Data'!C2 -> suresh.nair1@gmail.com | C49: =+MID(B49,FIND("@",B49)+1,LEN(B49)) -> gmail.com | D49: gmail.com
A50: 2 | B50: ='Raw Data'!C3 -> gaurav.patel2@learnhub.org | C50: =+MID(B50,FIND("@",B50)+1,LEN(B50)) -> learnhub.org
...

Sheet Aggregate Functions Practice
A1: AGGREGATE FUNCTIONS PRACTICE
A3: HOW TO USE THIS SHEET: Work through Tasks 1-7 below using SUM, AVERAGE, COUNT, COUNTA, MAX, and MIN. All formulas should reference the full data range on the Raw Data sheet (rows 2 to 53), not typed-in numbers. Type your formula into the yellow cell; a working Suggested Solution formula is shown in gray italics to the right.
A8: Legend: | B8: Yellow = Your Task
A10: # | B10: Task | C10: YOUR FORMULA (TASK)
A11: 1 | B11: [BEGINNER] SUM: Total of all Score1 values | C11: =SUM('Raw Data'!E2:E53) -> 3488
A12: 2 | B12: [BEGINNER] AVERAGE: Average of all Score2 values | C12: =SUM('Raw Data'!F:F) -> 3372
A13: 3 | B13: [BEGINNER] COUNT: How many students have a numeric Score2 (non-blank) | C13: =COUNT('Raw Data'!F1:F53) -> 51
A14: 4 | B14: [INTERMEDIATE] COUNTA: How many students have any Notes entered (non-blank text) | C14: =COUNTA('Raw Data'!J2:J53) -> 36
A15: 5 | B15: [BEGINNER] MAX: Highest score achieved in Score1 | C15: =MAX('Raw Data'!E2:E53) -> 100
A16: 6 | B16: [BEGINNER] MIN: Lowest score achieved in Score3 | C16: =MIN('Raw Data'!G2:G53) -> 50
A17: 7 | B17: [CHALLENGE] AVERAGE across all three score columns combined (one overall class average) | C17: =AVERAGE('Raw Data'!E2:G53) -> 70.318182
A19: BONUS: Grouped Analysis by Course (uses COUNTIFS / AVERAGEIFS)
A20: Instructions: Pick any course name from the Raw Data sheet and use COUNTIFS/AVERAGEIFS below to summarize just that course.
B21: Course to analyze (type a course name from Raw Data): | C21: Business Analytics
B22: Number of students in that course (COUNTIFS) | C22: =COUNTIF('Raw Data'!D2:D53,"Business Analytics") -> 6
B23: Average Score1 for that course (AVERAGEIFS) | C23: =AVERAGEIFS('Raw Data'!E2:E53, 'Raw Data'!D2:D53,"Business Analytics") -> 62.666667

Sheet Conditional Formatting
A1: CONDITIONAL FORMATTING PRACTICE
A3: HOW TO USE THIS SHEET: Each section below already has a Conditional Formatting rule APPLIED to a small demo table, so you can see the visual result immediately. Read the step-by-step instructions above each table describing exactly how that rule was built (Home tab > Conditional Formatting > ...). Then scroll to the 'YOUR TURN' practice table at the bottom of this sheet and try applying each rule yourself to that unformatted data.
A9: RULE 1: Color Scale on Scores
A10: Steps: Select the score range -> Home tab -> Conditional Formatting -> Color Scales -> pick Green-Yellow-Red (3-Color Scale). Higher scores shade green, lower scores shade red.
A11: Full Name | B11: Score1 | C11: Score2 | D11: Score3
A12: ='Raw Data'!B2 -> Suresh Nair | B12: ='Raw Data'!E2 -> 0 | C12: ='Raw Data'!F2 -> 54 | D12: ='Raw Data'!G2 -> 58
A13: ='Raw Data'!B3 -> Gaurav Patel | B13: ='Raw Data'!E3 -> 47 | C13: ='Raw Data'!F3 -> 41 | D13: ='Raw Data'!G3 -> 55
A14: ='Raw Data'!B4 -> Ishita Naidu | B14: ='Raw Data'!E4 -> 59 | C14: ='Raw Data'!F4 -> 68 | D14: ='Raw Data'!G4 -> 87
A15: ='Raw Data'!B5 -> Alok Mehta | B15: ='Raw Data'!E5 -> 62 | C15: ='Raw Data'!F5 -> 49 | D15: ='Raw Data'!G5 -> 63
A16: ='Raw Data'!B6 -> Kabir Reddy | B16: ='Raw Data'!E6 -> 83 | C16: ='Raw Data'!F6 -> 56 | D16: ='Raw Data'!G6 -> 52
A17: ='Raw Data'!B7 -> Kabir Patel | B17: ='Raw Data'!E7 -> 98 | C17: ='Raw Data'!F7 -> 80 | D17: ='Raw Data'!G7 -> 89
A18: ='Raw Data'!B8 -> Vikram Gupta | B18: ='Raw Data'!E8 -> 50 | C18: ='Raw Data'!F8 -> 94 | D18: ='Raw Data'!G8 -> 64
A19: ='Raw Data'!B9 -> Suresh Desai | B19: ='Raw Data'!E9 -> 67 | C19: ='Raw Data'!F9 -> 53 | D19: ='Raw Data'!G9 -> 92
A21: RULE 2: Highlight Above / Below Average
A22: Steps: Select the Score1 column -> Conditional Formatting -> Top/Bottom Rules -> Above Average (green fill) and again -> Below Average (red fill).
A23: Full Name | B23: Score1
A24: ='Raw Data'!B2 -> Suresh Nair | B24: ='Raw Data'!E2 -> 0
A25: ='Raw Data'!B3 -> Gaurav Patel | B25: ='Raw Data'!E3 -> 47
A26: ='Raw Data'!B4 -> Ishita Naidu | B26: ='Raw Data'!E4 -> 59
A27: ='Raw Data'!B5 -> Alok Mehta | B27: ='Raw Data'!E5 -> 62
A28: ='Raw Data'!B6 -> Kabir Reddy | B28: ='Raw Data'!E6 -> 83
A29: ='Raw Data'!B7 -> Kabir Patel | B29: ='Raw Data'!E7 -> 98
A30: ='Raw Data'!B8 -> Vikram Gupta | B30: ='Raw Data'!E8 -> 50
A31: ='Raw Data'!B9 -> Suresh Desai | B31: ='Raw Data'!E9 -> 67
A33: RULE 3: Data Bars
A34: Steps: Select the Score2 column -> Conditional Formatting -> Data Bars -> pick a Gradient Fill (e.g. blue). Longer bars mean higher scores, letting you compare values at a glance.
A35: Full Name | B35: Score2
A36: ='Raw Data'!B2 -> Suresh Nair | B36: ='Raw Data'!F2 -> 54
A37: ='Raw Data'!B3 -> Gaurav Patel | B37: ='Raw Data'!F3 -> 41
A38: ='Raw Data'!B4 -> Ishita Naidu | B38: ='Raw Data'!F4 -> 68
A39: ='Raw Data'!B5 -> Alok Mehta | B39: ='Raw Data'!F5 -> 49
A40: ='Raw Data'!B6 -> Kabir Reddy | B40: ='Raw Data'!F6 -> 56
A41: ='Raw Data'!B7 -> Kabir Patel | B41: ='Raw Data'!F7 -> 80
A42: ='Raw Data'!B8 -> Vikram Gupta | B42: ='Raw Data'!F8 -> 94
A43: ='Raw Data'!B9 -> Suresh Desai | B43: ='Raw Data'!F9 -> 53
A45: RULE 4: Icon Sets
A46: Steps: Select the Score3 column -> Conditional Formatting -> Icon Sets -> 3 Traffic Lights (Unrimmed). Green = high score, yellow = mid, red = low.
A47: Full Name | B47: Score3
A48: ='Raw Data'!B2 -> Suresh Nair | B48: ='Raw Data'!G2 -> 58
A49: ='Raw Data'!B3 -> Gaurav Patel | B49: ='Raw Data'!G3 -> 55
...

Sheet Dashboard
A1: CLASS DASHBOARD - LIVE SUMMARY
A3: Every figure below is a live formula pulling directly from the Raw Data sheet. If Raw Data changes, this Dashboard updates automatically - no manual recalculation needed.
B6: KEY METRICS | E6: STUDENTS PER COURSE
B7: Total Students Enrolled | C7: =COUNTA('Raw Data'!A2:A53) -> 52 | E7: Course | F7: Count
B8: Overall Average Score (all 3 tests) | C8: =AVERAGE('Raw Data'!E2:G53) -> 70.318182 | E8: Data Science Fundamentals | F8: =COUNTIF('Raw Data'!D2:D53,E8) -> 7
B9: Highest Individual Score | C9: =MAX('Raw Data'!E2:G53) -> 100 | E9: Advanced Excel | F9: =COUNTIF('Raw Data'!D2:D53,E9) -> 5
B10: Lowest Individual Score | C10: =MIN('Raw Data'!E2:G53) -> 41 | E10: Python for Analytics | F10: =COUNTIF('Raw Data'!D2:D53,E10) -> 6
B11: Students Currently Active | C11: =COUNTIF('Raw Data'!I2:I53,"Active") -> 31 | E11: Business Analytics | F11: =COUNTIF('Raw Data'!D2:D53,E11) -> 6
B12: Students Completed | C12: =COUNTIF('Raw Data'!I2:I53,"Completed") -> 13 | E12: Machine Learning Basics | F12: =COUNTIF('Raw Data'!D2:D53,E12) -> 9
B13: Students Dropped | C13: =COUNTIF('Raw Data'!I2:I53,"Dropped") -> 5 | E13: SQL for Data Analysis | F13: =COUNTIF('Raw Data'!D2:D53,E13) -> 7
B14: Earliest Enrollment Date | C14: =MIN('Raw Data'!H2:H53) -> 45327 | E14: Power BI Essentials | F14: =COUNTIF('Raw Data'!D2:D53,E14) -> 6
B15: Latest Enrollment Date | C15: =MAX('Raw Data'!H2:H53) -> 45698 | E15: Statistics for Data Science | F15: =COUNTIF('Raw Data'!D2:D53,E15) -> 6
