Workbook

Sheet Sheet1_Questions
A1: 📊 TechMart Distributors – Data Analytics Practice Workbook
A2: Topics: Data Types · Validation · Duplicates · Conditional Formatting · Sorting & Filtering · Functions · Lookup · Logic
A3: Dataset lives in Sheet2_RawData (312 rows, Jan–Dec 2024). You are the analyst. Don't just use formulas — think like a problem solver.
A6: SECTION 1: Data Cleaning & Validation
A7: Identify problems in raw data before any analysis. A clean dataset is the foundation of every business decision.
A8: # | B8: Question | C8: Skill Tag | D8: Difficulty | E8: Your Answer | F8: Formula / Steps Used | G8: Business Insight (write 1 sentence) | H8: Self-Check ✓ | I8: Notes | J8: Notes
A9: 1 | B9: Open Sheet2_RawData. Scan the 'Sales Rep' column — some cells are blank. Using a COUNTBLANK function, find exactly how many sales rep entries are missing. Then, as a business analyst, explain: should these orders be assigned to a default rep or excluded from performance reports? | C9: COUNTBLANK, Data Audit | D9: Intermediate | E9: =COUNTBLANK(Sheet2_RawData!$D$2:$D$313) -> 0 | H9: ☐
A10: 2 | B10: The 'Unit Price' column has a cell with the text 'N/A' instead of a number. Use ISNUMBER + IF to flag all rows where Unit Price is not a valid number. How many such rows exist? What risk does this create if you run a SUM formula on the whole column? | C10: ISNUMBER, Error Detection | D10: Intermediate | E10: =ISNUMBER(Sheet2_RawData!$I2) -> TRUE | H10: ☐
A11: 3 | B11: Remove all duplicate Order IDs from the dataset. Before deleting, use COUNTIF to count how many Order IDs appear more than once. After removing duplicates (Data → Remove Duplicates), how many rows remain? Write the exact count. | C11: COUNTIF, Remove Duplicates | D11: Intermediate | E11: =SUMPRODUCT((COUNTIF(Sheet2_RawData!$A$2:$A$313, Sheet2_RawData!$A$2:$A$313)>1)*1) -> 23 | H11: ☐
A12: 4 | B12: A new intern added orders with 'Status' values like 'delivered', 'PENDING', and 'cancelled' — inconsistent capitalisation. Use Data Validation to create a dropdown list for the Status column allowing only: Delivered, Pending, Cancelled, Returned, Processing. How does this prevent future data quality issues? | C12: Data Validation, Data Types | D12: Intermediate | H12: ☐
A13: 5 | B13: Use conditional formatting to highlight all rows where Discount > 15% in orange. Now count how many orders received more than 15% discount using COUNTIF. What percentage of total orders is this? Is a discount rate above 15% sustainable from a business perspective? | C13: Conditional Formatting, COUNTIF | D13: Intermediate | E13: =COUNTIF(Sheet2_RawData!J2:J313,">0.15") -> 36 | H13: ☐
A14: 6 | B14: Apply conditional formatting with a colour scale on the 'Quantity' column from green (low) to red (high). What does the visual pattern tell you about typical order sizes? Which region or category tends to have the largest order volumes? (Use Sort & Filter to validate your visual observation.) | C14: Conditional Formatting, Sorting | D14: Advanced | H14: ☐
A15: 7 | B15: Create a helper column called 'Revenue (₹)' that calculates: Quantity × Unit Price × (1 – Discount). Make sure the formula handles the text error in Unit Price gracefully using IFERROR. What is the total revenue across all valid rows? | C15: IFERROR, Formula Construction | D15: Intermediate | E15: =SUM(Sheet2_RawData!M1:M313) -> 18013167 | H15: ☐
A16: 8 | B16: Sort the entire dataset by Region (A→Z), then by Category (A→Z), then by Revenue descending. What is the top-selling product in the East region? Write the product name and its revenue. | C16: Sorting, Multi-level Sort | D16: Intermediate | E16: =Sheet2_RawData!M13 -> 124989.63 | H16: ☐
A17: 9 | B17: Use AutoFilter to show only 'Cancelled' and 'Returned' orders. Calculate the total lost revenue (use the Revenue helper column if built). Which Sales Rep has the most cancellations? This is a critical business KPI — what action would you recommend? | C17: Filter, Business Analysis | D17: Advanced | E17: =SUM(Sheet2_RawData!M2:M309) -> 17712739 | F17: \ | H17: ☐
A18: 10 | B18: Use a filter to find all orders placed in Q3 2024 (July–September). Then, within Q3, find the top 5 customers by total order value. Hint: use MONTH() and YEAR() as helper columns to isolate Q3 rows. | C18: MONTH, YEAR, Filter, Sorting | D18: Advanced | H18: ☐
A20: SECTION 2: Counting & Statistical Functions
A21: Measure performance, spot outliers, and summarise data the way a business analyst would present to management.
A22: # | B22: Question | C22: Skill Tag | D22: Difficulty | E22: Your Answer | F22: Formula / Steps Used | G22: Business Insight (write 1 sentence) | H22: Self-Check ✓ | I22: Notes | J22: Notes
A23: 11 | B23: Use COUNTA to count the total number of non-empty rows in the 'Order ID' column. Then use COUNT to count only numeric values in the 'Quantity' column. Why might these two numbers differ, and what does that tell you about data quality? | C23: COUNTA, COUNT, Data Quality | D23: Intermediate | H23: ☐
A24: 12 | B24: Use COUNTIF to find: (a) how many orders are from the 'North' region, (b) how many orders have the product 'Laptop', (c) how many orders have a Discount of exactly 0%. Present these three results in a small summary table beside the data. | C24: COUNTIF, Summary Table | D24: Intermediate | H24: ☐
A25: 13 | B25: Use COUNTIFS to find orders that are BOTH from the 'Electronics' category AND have 'Delivered' status AND have a Quantity > 20. This is a multi-condition count — describe why COUNTIFS is more powerful than running three separate filters. | C25: COUNTIFS, Multi-criteria | D25: Advanced | H25: ☐
A26: 14 | B26: Calculate the AVERAGE, MEDIAN, and MODE of the 'Unit Price' column. If the average is much higher than the median, what does that suggest about the price distribution? What business decision could you make based on this insight? | C26: AVERAGE, MEDIAN, MODE | D26: Intermediate | H26: ☐
A27: 15 | B27: Use AVERAGEIF to find the average unit price for each Category separately. Which category has the highest average price? Which has the lowest? Present this as a 5-row summary table. | C27: AVERAGEIF, Category Analysis | D27: Intermediate | H27: ☐
A28: 16 | B28: Use AVERAGEIFS to find the average revenue per order for: Female-region = 'South' AND Status = 'Delivered'. Then compare it with the overall average revenue. Is the South region performing above or below average for successful deliveries? | C28: AVERAGEIFS, Regional KPI | D28: Advanced | H28: ☐
A29: 17 | B29: Find the MAX and MIN values in the 'Quantity' column. Then use LARGE(range,2) and SMALL(range,2) to find the 2nd largest and 2nd smallest order quantities. Why is LARGE/SMALL more flexible than MAX/MIN for business reporting? | C29: MAX, MIN, LARGE, SMALL | D29: Intermediate | H29: ☐
A30: 18 | B30: Create a frequency distribution: count how many orders fall into these Quantity buckets — [1–10], [11–20], [21–30], [31–40], [41–50]. Use COUNTIFS for each bucket. Which bucket has the most orders? What does this tell the warehouse team about typical shipment sizes? | C30: COUNTIFS, Distribution Analysis | D30: Advanced | H30: ☐
A31: 19 | B31: Use SUMIF to calculate total revenue for each Region. Then calculate each region's % share of total revenue using absolute references ($). Which region contributes the most? Format the % column with one decimal place. | C31: SUMIF, Absolute Reference, % Share | D31: Advanced | H31: ☐
A32: 20 | B32: Use SUMIFS to find total revenue where: Category = 'Industrial Tools' AND Status = 'Delivered' AND Discount = 0%. This is the 'clean revenue' from Industrial Tools. Compare this to total Industrial Tools revenue. What % of revenue is discounted? | C32: SUMIFS, Business Margin Analysis | D32: Expert | H32: ☐
A34: SECTION 3: Logical Functions & Conditional Intelligence
A35: Build smart classifications, flag risk, and automate decisions — the core of any analytical model.
A36: # | B36: Question | C36: Skill Tag | D36: Difficulty | E36: Your Answer | F36: Formula / Steps Used | G36: Business Insight (write 1 sentence) | H36: Self-Check ✓ | I36: Notes | J36: Notes
A37: 21 | B37: Add a column 'Order Size' using IF: if Quantity ≥ 30 label it 'Large', else if Quantity ≥ 15 label it 'Medium', else 'Small'. Use nested IFs. Count how many orders fall into each category using COUNTIF. | C37: Nested IF, Classification | D37: Intermediate | H37: ☐
A38: 22 | B38: Create a 'Risk Flag' column using IF + AND: flag as 'HIGH RISK' if Status = 'Cancelled' AND Discount > 10%, otherwise 'OK'. How many high-risk orders exist? What is the total revenue value at risk? | C38: IF, AND, Risk Flagging | D38: Intermediate | H38: ☐
A39: 23 | B39: Build a 'Bonus Eligible' column using IF + OR: a sales rep is bonus-eligible for an order if: Status = 'Delivered' OR (Status = 'Pending' AND Discount = 0%). Count bonus-eligible orders per Sales Rep using COUNTIF. | C39: IF, OR, Incentive Modelling | D39: Advanced | H39: ☐
A40: 24 | B40: Use IFS (not nested IF) to create a 'Discount Category' column: 0% → 'No Discount', 1–10% → 'Low', 11–20% → 'Medium', >20% → 'High'. Rewrite the same logic using nested IF. Which approach is more readable and why does readability matter in a business setting? | C40: IFS, Nested IF, Readability | D40: Advanced | H40: ☐
A41: 25 | B41: Add a 'Performance Score' column using this rule: IF Delivered AND No Discount → 3 points; IF Delivered AND Discount ≤ 10% → 2 points; IF Delivered AND Discount > 10% → 1 point; All other statuses → 0 points. Sum the total score per Sales Rep. Who is the top performer? | C41: IF, AND, Performance Scoring | D41: Expert | H41: ☐
A42: 26 | B42: Use NOT to find all orders that are NOT from the 'North' or 'South' region. Combine NOT with OR inside an IF to add a 'Central/East/West' flag column. Count these orders and calculate their total revenue. | C42: NOT, OR, IF, Revenue Analysis | D42: Advanced | H42: ☐
A43: 27 | B43: Create a 'Delivery Alert' column: mark 'REVIEW' if Status = 'Pending' AND Order Date is more than 90 days ago from today (use TODAY()). Mark 'OVERDUE' if more than 180 days. All others = 'OK'. How many orders are overdue? | C43: IF, AND, TODAY, Date Logic | D43: Advanced | H43: ☐
A44: 28 | B44: Use IFERROR to build a safe 'Avg Price Check' column: divide Unit Price by Quantity — but use IFERROR to return 'Data Error' instead of crashing when a non-numeric value is encountered. Why is IFERROR essential in production dashboards? | C44: IFERROR, Error Handling | D44: Intermediate | H44: ☐
...

Sheet Sheet2_RawData
A1: Order ID | B1: Order Date | C1: Customer ID | D1: Sales Rep | E1: Region | F1: Category | G1: Product | H1: Quantity | I1: Unit Price (₹) | J1: Discount | K1: Status | M1: Revenue | N1: year | O1: month | P1: week
A2: ORD-59823 | B2: 45343 | C2: CUST-015 | D2: =_xlfn.MODE.SNGL(D1:D288) -> 0 | E2: North | F2: Safety Equipment | G2: Vest | H2: 50 | I2: 1482.47 | J2: 0 | K2: Returned | M2: =IFERROR( Sheet2_RawData!$H113 * Sheet2_RawData!$I113 * (1 - Sheet2_RawData!$J113), "" ) -> 2561.04 | N2: =YEAR(Sheet2_RawData!$B2) -> 2024 | O2: =MONTH(Sheet2_RawData!$B2) -> 2
A3: ORD-78955 | B3: 45507 | C3: CUST-021 | D3: Neha Gupta | E3: South | F3: Electronics | G3: Keyboard | H3: 2 | I3: 912.52 | J3: 0 | K3: Delivered | M3: =IFERROR( Sheet2_RawData!$H55 * Sheet2_RawData!$I55 * (1 - Sheet2_RawData!$J55), "" ) -> 28737.504 | N3: =YEAR(Sheet2_RawData!$B3) -> 2024 | O3: =MONTH(Sheet2_RawData!$B3) -> 8 | P3: =AND($N3=2024, OR($O3=7, $O3=8, $O3=9)) -> TRUE | Q3: =SUMIFS(Sheet2_RawData!$M$3:$M$313, Sheet2_RawData!$P$3:$P$313, TRUE) -> 5733183.3
A4: ORD-25389 | B4: 45645 | C4: CUST-011 | D4: Vikram Nair | E4: West | F4: Electronics | G4: Laptop | H4: 26 | I4: 3446.06 | J4: 0.15 | K4: Cancelled | M4: =IFERROR( Sheet2_RawData!$H277 * Sheet2_RawData!$I277 * (1 - Sheet2_RawData!$J277), "" ) -> 9350.784 | N4: =YEAR(Sheet2_RawData!$B4) -> 2024 | O4: =MONTH(Sheet2_RawData!$B4) -> 12
A5: ORD-99381 | B5: 45336 | C5: CUST-009 | D5: Priya Shah | E5: South | F5: Office Supplies | G5: Stapler | H5: 5 | I5: 2287.61 | J5: 0.15 | K5: Delivered | M5: =IFERROR( Sheet2_RawData!$H152 * Sheet2_RawData!$I152 * (1 - Sheet2_RawData!$J152), "" ) -> 3689.72 | N5: =YEAR(Sheet2_RawData!$B5) -> 2024 | O5: =MONTH(Sheet2_RawData!$B5) -> 2
A6: ORD-36724 | B6: 45645 | C6: CUST-013 | D6: Priya Shah | E6: Central | F6: Furniture | G6: Desk | H6: 2 | I6: 2233.14 | J6: 0.05 | K6: Delivered | M6: =IFERROR( Sheet2_RawData!$H312 * Sheet2_RawData!$I312 * (1 - Sheet2_RawData!$J312), "" ) -> 123922.62 | N6: =YEAR(Sheet2_RawData!$B6) -> 2024 | O6: =MONTH(Sheet2_RawData!$B6) -> 12
A7: ORD-57472 | B7: 45513 | C7: CUST-022 | D7: Rahul Kumar | E7: North | F7: Industrial Tools | G7: Safety Gloves | H7: 1 | I7: 4255.4 | J7: 0.2 | K7: Delivered | M7: =IFERROR( Sheet2_RawData!$H173 * Sheet2_RawData!$I173 * (1 - Sheet2_RawData!$J173), "" ) -> 210818.7 | N7: =YEAR(Sheet2_RawData!$B7) -> 2024 | O7: =MONTH(Sheet2_RawData!$B7) -> 8 | P7: =AND($N7=2024, OR($O7=7, $O7=8, $O7=9)) -> TRUE
A8: ORD-50768 | B8: 45375 | C8: CUST-024 | D8: Vikram Nair | E8: West | F8: Safety Equipment | G8: Vest | H8: 11 | I8: 3049.17 | J8: 0.15 | K8: Pending | M8: =IFERROR( Sheet2_RawData!$H39 * Sheet2_RawData!$I39 * (1 - Sheet2_RawData!$J39), "" ) -> 93694.177 | N8: =YEAR(Sheet2_RawData!$B8) -> 2024 | O8: =MONTH(Sheet2_RawData!$B8) -> 3
A9: ORD-96752 | B9: 45576 | C9: CUST-030 | D9: Vikram Nair | E9: West | F9: Industrial Tools | G9: Drill Machine | H9: 19 | I9: 2143.89 | J9: 0.15 | K9: Processing | M9: =IFERROR( Sheet2_RawData!$H16 * Sheet2_RawData!$I16 * (1 - Sheet2_RawData!$J16), "" ) -> 29753.856 | N9: =YEAR(Sheet2_RawData!$B9) -> 2024 | O9: =MONTH(Sheet2_RawData!$B9) -> 10
A10: ORD-51245 | B10: 45582 | C10: CUST-003 | D10: Sneha Patel | E10: North | F10: Furniture | G10: Cabinet | H10: 21 | I10: 2035.77 | J10: 0 | K10: Delivered | M10: =IFERROR( Sheet2_RawData!$H289 * Sheet2_RawData!$I289 * (1 - Sheet2_RawData!$J289), "" ) -> 84367.98 | N10: =YEAR(Sheet2_RawData!$B10) -> 2024 | O10: =MONTH(Sheet2_RawData!$B10) -> 10
A11: ORD-70260 | B11: 45301 | C11: CUST-023 | D11: Rahul Kumar | E11: Central | F11: Safety Equipment | G11: Vest | H11: 5 | I11: 2015.5 | J11: 0.15 | K11: Delivered | M11: =IFERROR( Sheet2_RawData!$H286 * Sheet2_RawData!$I286 * (1 - Sheet2_RawData!$J286), "" ) -> 194818.38 | N11: =YEAR(Sheet2_RawData!$B11) -> 2024 | O11: =MONTH(Sheet2_RawData!$B11) -> 1
A12: ORD-43246 | B12: 45483 | C12: CUST-002 | D12: Rahul Kumar | E12: Central | F12: Safety Equipment | G12: Ear Plugs | H12: 25 | I12: 4372.99 | J12: 0 | K12: Pending | M12: =IFERROR( Sheet2_RawData!$H26 * Sheet2_RawData!$I26 * (1 - Sheet2_RawData!$J26), "" ) -> 14848.32 | N12: =YEAR(Sheet2_RawData!$B12) -> 2024 | O12: =MONTH(Sheet2_RawData!$B12) -> 7 | P12: =AND($N12=2024, OR($O12=7, $O12=8, $O12=9)) -> TRUE
A13: ORD-74038 | B13: 45500 | C13: CUST-001 | D13: Rahul Kumar | E13: East | F13: Office Supplies | G13: Binder | H13: 34 | I13: 4742.91 | J13: 0 | K13: Delivered | M13: =IFERROR( Sheet2_RawData!$H298 * Sheet2_RawData!$I298 * (1 - Sheet2_RawData!$J298), "" ) -> 124989.63 | N13: =YEAR(Sheet2_RawData!$B13) -> 2024 | O13: =MONTH(Sheet2_RawData!$B13) -> 7 | P13: =AND($N13=2024, OR($O13=7, $O13=8, $O13=9)) -> TRUE
A14: ORD-18357 | B14: 45468 | C14: CUST-001 | D14: Vikram Nair | E14: West | F14: Office Supplies | G14: Pen Set | H14: 48 | I14: 1128.61 | J14: 0 | K14: Delivered | M14: =IFERROR( Sheet2_RawData!$H257 * Sheet2_RawData!$I257 * (1 - Sheet2_RawData!$J257), "" ) -> 36965.664 | N14: =YEAR(Sheet2_RawData!$B14) -> 2024 | O14: =MONTH(Sheet2_RawData!$B14) -> 6
A15: ORD-24945 | B15: 45616 | C15: CUST-022 | D15: Vikram Nair | E15: West | F15: Safety Equipment | G15: Helmet | H15: 15 | I15: 1698.69 | J15: 0 | K15: Delivered | M15: =IFERROR( Sheet2_RawData!$H119 * Sheet2_RawData!$I119 * (1 - Sheet2_RawData!$J119), "" ) -> 23978.37 | N15: =YEAR(Sheet2_RawData!$B15) -> 2024 | O15: =MONTH(Sheet2_RawData!$B15) -> 11
A16: ORD-17592 | B16: 45414 | C16: CUST-002 | D16: Deepa Joshi | E16: East | F16: Electronics | G16: Printer | H16: 8 | I16: 4649.04 | J16: 0.2 | K16: Cancelled | M16: =IFERROR( Sheet2_RawData!$H252 * Sheet2_RawData!$I252 * (1 - Sheet2_RawData!$J252), "" ) -> 24146.256 | N16: =YEAR(Sheet2_RawData!$B16) -> 2024 | O16: =MONTH(Sheet2_RawData!$B16) -> 5
A17: ORD-71213 | B17: 45502 | C17: CUST-013 | D17: Amit Sharma | E17: West | F17: Industrial Tools | G17: Wrench Set | H17: 7 | I17: 529.81 | J17: 0.05 | K17: Delivered | M17: =IFERROR( Sheet2_RawData!$H284 * Sheet2_RawData!$I284 * (1 - Sheet2_RawData!$J284), "" ) -> 180998.5 | N17: =YEAR(Sheet2_RawData!$B17) -> 2024 | O17: =MONTH(Sheet2_RawData!$B17) -> 7 | P17: =AND($N17=2024, OR($O17=7, $O17=8, $O17=9)) -> TRUE
A18: ORD-89131 | B18: 45468 | C18: CUST-022 | D18: Sneha Patel | E18: South | F18: Office Supplies | G18: Paper Ream | H18: 7 | I18: 509.09 | J18: 0 | K18: Delivered | M18: =IFERROR( Sheet2_RawData!$H244 * Sheet2_RawData!$I244 * (1 - Sheet2_RawData!$J244), "" ) -> 2470.23 | N18: =YEAR(Sheet2_RawData!$B18) -> 2024 | O18: =MONTH(Sheet2_RawData!$B18) -> 6
A19: ORD-89905 | B19: 45322 | C19: CUST-020 | D19: Deepa Joshi | E19: West | F19: Safety Equipment | G19: Goggles | H19: 38 | I19: 4950.65 | J19: 0 | K19: Pending | M19: =IFERROR( Sheet2_RawData!$H17 * Sheet2_RawData!$I17 * (1 - Sheet2_RawData!$J17), "" ) -> 3523.2365 | N19: =YEAR(Sheet2_RawData!$B19) -> 2024 | O19: =MONTH(Sheet2_RawData!$B19) -> 1
A20: ORD-69243 | B20: 45484 | C20: CUST-032 | D20: Amit Sharma | E20: South | F20: Furniture | G20: Cabinet | H20: 10 | I20: 2908.26 | J20: 0 | K20: Pending | M20: =IFERROR( Sheet2_RawData!$H89 * Sheet2_RawData!$I89 * (1 - Sheet2_RawData!$J89), "" ) -> 121563.28 | N20: =YEAR(Sheet2_RawData!$B20) -> 2024 | O20: =MONTH(Sheet2_RawData!$B20) -> 7 | P20: =AND($N20=2024, OR($O20=7, $O20=8, $O20=9)) -> TRUE
A21: ORD-39389 | B21: 45471 | C21: CUST-006 | D21: Vikram Nair | E21: West | F21: Industrial Tools | G21: Safety Gloves | H21: 31 | I21: 145.95 | J21: 0.1 | K21: Delivered | M21: =IFERROR( Sheet2_RawData!$H192 * Sheet2_RawData!$I192 * (1 - Sheet2_RawData!$J192), "" ) -> 17082.6 | N21: =YEAR(Sheet2_RawData!$B21) -> 2024 | O21: =MONTH(Sheet2_RawData!$B21) -> 6
A22: ORD-82362 | B22: 45414 | C22: CUST-031 | D22: Priya Shah | E22: South | F22: Electronics | G22: Monitor | H22: 16 | I22: 3493.35 | J22: 0.15 | K22: Delivered | M22: =IFERROR( Sheet2_RawData!$H208 * Sheet2_RawData!$I208 * (1 - Sheet2_RawData!$J208), "" ) -> 63507.36 | N22: =YEAR(Sheet2_RawData!$B22) -> 2024 | O22: =MONTH(Sheet2_RawData!$B22) -> 5
A23: ORD-58916 | B23: 45525 | C23: CUST-015 | D23: Rohan Desai | E23: West | F23: Electronics | G23: Laptop | H23: 5 | I23: 3550.49 | J23: 0 | K23: Delivered | M23: =IFERROR( Sheet2_RawData!$H187 * Sheet2_RawData!$I187 * (1 - Sheet2_RawData!$J187), "" ) -> 93243.8 | N23: =YEAR(Sheet2_RawData!$B23) -> 2024 | O23: =MONTH(Sheet2_RawData!$B23) -> 8 | P23: =AND($N23=2024, OR($O23=7, $O23=8, $O23=9)) -> TRUE
A24: ORD-50499 | B24: 45431 | C24: CUST-039 | D24: Arjun Mehta | E24: Central | F24: Safety Equipment | G24: Ear Plugs | H24: 43 | I24: 4155.83 | J24: 0 | K24: Delivered | M24: =IFERROR( Sheet2_RawData!$H238 * Sheet2_RawData!$I238 * (1 - Sheet2_RawData!$J238), "" ) -> 3282.345 | N24: =YEAR(Sheet2_RawData!$B24) -> 2024 | O24: =MONTH(Sheet2_RawData!$B24) -> 5
A25: ORD-60965 | B25: 45511 | C25: CUST-026 | D25: Amit Sharma | E25: South | F25: Industrial Tools | G25: Wrench Set | H25: 2 | I25: 3700.07 | J25: 0 | K25: Delivered | M25: =IFERROR( Sheet2_RawData!$H272 * Sheet2_RawData!$I272 * (1 - Sheet2_RawData!$J272), "" ) -> 9350.784 | N25: =YEAR(Sheet2_RawData!$B25) -> 2024 | O25: =MONTH(Sheet2_RawData!$B25) -> 8 | P25: =AND($N25=2024, OR($O25=7, $O25=8, $O25=9)) -> TRUE
A26: ORD-83526 | B26: 45511 | C26: CUST-036 | D26: Kavya Iyer | E26: North | F26: Industrial Tools | G26: Wrench Set | H26: 24 | I26: 618.68 | J26: 0 | K26: Pending | M26: =IFERROR( Sheet2_RawData!$H141 * Sheet2_RawData!$I141 * (1 - Sheet2_RawData!$J141), "" ) -> 7028.208 | N26: =YEAR(Sheet2_RawData!$B26) -> 2024 | O26: =MONTH(Sheet2_RawData!$B26) -> 8 | P26: =AND($N26=2024, OR($O26=7, $O26=8, $O26=9)) -> TRUE
A27: ORD-94319 | B27: 45640 | C27: CUST-030 | D27: Rohan Desai | E27: East | F27: Safety Equipment | G27: Goggles | H27: 35 | I27: 1744.52 | J27: 0 | K27: Pending | M27: =IFERROR( Sheet2_RawData!$H32 * Sheet2_RawData!$I32 * (1 - Sheet2_RawData!$J32), "" ) -> 4850.973 | N27: =YEAR(Sheet2_RawData!$B27) -> 2024 | O27: =MONTH(Sheet2_RawData!$B27) -> 12
A28: ORD-97670 | B28: 45464 | C28: CUST-032 | D28: Sneha Patel | E28: Central | F28: Safety Equipment | G28: Ear Plugs | H28: 15 | I28: 1401.03 | J28: 0.05 | K28: Delivered | M28: =IFERROR( Sheet2_RawData!$H93 * Sheet2_RawData!$I93 * (1 - Sheet2_RawData!$J93), "" ) -> 27240.192 | N28: =YEAR(Sheet2_RawData!$B28) -> 2024 | O28: =MONTH(Sheet2_RawData!$B28) -> 6
A29: ORD-31842 | B29: 45510 | C29: CUST-021 | D29: Priya Shah | E29: North | F29: Office Supplies | G29: Paper Ream | H29: 43 | I29: 1513.42 | J29: 0.05 | K29: Pending | M29: =IFERROR( Sheet2_RawData!$H250 * Sheet2_RawData!$I250 * (1 - Sheet2_RawData!$J250), "" ) -> 146067.57 | N29: =YEAR(Sheet2_RawData!$B29) -> 2024 | O29: =MONTH(Sheet2_RawData!$B29) -> 8 | P29: =AND($N29=2024, OR($O29=7, $O29=8, $O29=9)) -> TRUE
A30: ORD-24534 | B30: 45512 | C30: CUST-027 | D30: Deepa Joshi | E30: Central | F30: Industrial Tools | G30: Voltage Tester | H30: 18 | I30: 1117.07 | J30: 0.1 | K30: Delivered | M30: =IFERROR( Sheet2_RawData!$H8 * Sheet2_RawData!$I8 * (1 - Sheet2_RawData!$J8), "" ) -> 28509.739 | N30: =YEAR(Sheet2_RawData!$B30) -> 2024 | O30: =MONTH(Sheet2_RawData!$B30) -> 8 | P30: =AND($N30=2024, OR($O30=7, $O30=8, $O30=9)) -> TRUE
A31: ORD-73298 | B31: 45558 | C31: CUST-010 | D31: Priya Shah | E31: North | F31: Office Supplies | G31: Stapler | H31: 23 | I31: 1593.86 | J31: 0.05 | K31: Cancelled | M31: =IFERROR( Sheet2_RawData!$H302 * Sheet2_RawData!$I302 * (1 - Sheet2_RawData!$J302), "" ) -> 14088.384 | N31: =YEAR(Sheet2_RawData!$B31) -> 2024 | O31: =MONTH(Sheet2_RawData!$B31) -> 9 | P31: =AND($N31=2024, OR($O31=7, $O31=8, $O31=9)) -> TRUE
A32: ORD-39015 | B32: 45604 | C32: CUST-015 | D32: Priya Shah | E32: East | F32: Safety Equipment | G32: Goggles | H32: 31 | I32: 173.87 | J32: 0.1 | K32: Delivered | M32: =IFERROR( Sheet2_RawData!$H217 * Sheet2_RawData!$I217 * (1 - Sheet2_RawData!$J217), "" ) -> 50920.95 | N32: =YEAR(Sheet2_RawData!$B32) -> 2024 | O32: =MONTH(Sheet2_RawData!$B32) -> 11
A33: ORD-92050 | B33: 45381 | C33: CUST-020 | D33: Amit Sharma | E33: South | F33: Furniture | G33: Meeting Table | H33: 18 | I33: 351.74 | J33: 0.1 | K33: Returned | M33: =IFERROR( Sheet2_RawData!$H144 * Sheet2_RawData!$I144 * (1 - Sheet2_RawData!$J144), "" ) -> 15310.608 | N33: =YEAR(Sheet2_RawData!$B33) -> 2024 | O33: =MONTH(Sheet2_RawData!$B33) -> 3
A34: ORD-13969 | B34: 45619 | C34: CUST-017 | D34: Neha Gupta | E34: North | F34: Electronics | G34: Laptop | H34: 42 | I34: 1093.5 | J34: 0.1 | K34: Delivered | M34: =IFERROR( Sheet2_RawData!$H194 * Sheet2_RawData!$I194 * (1 - Sheet2_RawData!$J194), "" ) -> 10836.973 | N34: =YEAR(Sheet2_RawData!$B34) -> 2024 | O34: =MONTH(Sheet2_RawData!$B34) -> 11
A35: ORD-12125 | B35: 45366 | C35: CUST-024 | D35: Sneha Patel | E35: East | F35: Electronics | G35: Scanner | H35: 21 | I35: 2098.95 | J35: 0.1 | K35: Returned | M35: =IFERROR( Sheet2_RawData!$H150 * Sheet2_RawData!$I150 * (1 - Sheet2_RawData!$J150), "" ) -> 7781.47 | N35: =YEAR(Sheet2_RawData!$B35) -> 2024 | O35: =MONTH(Sheet2_RawData!$B35) -> 3
A36: ORD-41946 | B36: 45533 | C36: CUST-033 | D36: Vikram Nair | E36: West | F36: Electronics | G36: Monitor | H36: 46 | I36: 1403.45 | J36: 0.2 | K36: Delivered | M36: =IFERROR( Sheet2_RawData!$H108 * Sheet2_RawData!$I108 * (1 - Sheet2_RawData!$J108), "" ) -> 159355.84 | N36: =YEAR(Sheet2_RawData!$B36) -> 2024 | O36: =MONTH(Sheet2_RawData!$B36) -> 8 | P36: =AND($N36=2024, OR($O36=7, $O36=8, $O36=9)) -> TRUE
A37: ORD-42780 | B37: 45509 | C37: CUST-029 | D37: Priya Shah | E37: South | F37: Office Supplies | G37: Binder | H37: 23 | I37: 4938.88 | J37: 0 | K37: Pending | M37: =IFERROR( Sheet2_RawData!$H77 * Sheet2_RawData!$I77 * (1 - Sheet2_RawData!$J77), "" ) -> 47154.63 | N37: =YEAR(Sheet2_RawData!$B37) -> 2024 | O37: =MONTH(Sheet2_RawData!$B37) -> 8 | P37: =AND($N37=2024, OR($O37=7, $O37=8, $O37=9)) -> TRUE
A38: ORD-65353 | B38: 45353 | C38: CUST-034 | D38: Sneha Patel | E38: Central | F38: Electronics | G38: Monitor | H38: 44 | I38: 2253.08 | J38: 0 | K38: Pending | M38: =IFERROR( Sheet2_RawData!$H149 * Sheet2_RawData!$I149 * (1 - Sheet2_RawData!$J149), "" ) -> 12450.915 | N38: =YEAR(Sheet2_RawData!$B38) -> 2024 | O38: =MONTH(Sheet2_RawData!$B38) -> 3
A39: ORD-15683 | B39: 45606 | C39: CUST-024 | D39: Deepa Joshi | E39: West | F39: Electronics | G39: Laptop | H39: 33 | I39: 2988.65 | J39: 0.05 | K39: Delivered | M39: =IFERROR( Sheet2_RawData!$H143 * Sheet2_RawData!$I143 * (1 - Sheet2_RawData!$J143), "" ) -> 46160.83 | N39: =YEAR(Sheet2_RawData!$B39) -> 2024 | O39: =MONTH(Sheet2_RawData!$B39) -> 11
A40: ORD-38971 | B40: 45586 | C40: CUST-015 | D40: Vikram Nair | E40: North | F40: Electronics | G40: Laptop | H40: 33 | I40: 3746.92 | J40: 0.1 | K40: Pending | M40: =IFERROR( Sheet2_RawData!$H199 * Sheet2_RawData!$I199 * (1 - Sheet2_RawData!$J199), "" ) -> 28617.57 | N40: =YEAR(Sheet2_RawData!$B40) -> 2024 | O40: =MONTH(Sheet2_RawData!$B40) -> 10
...
